Traceback (most recent call last):
  File "<pyshell#15>", line 2, in <module>
Exception: some error messsage
